Workbook

Sheet Test Cases
A1: Epic | B1: Test Case ID | C1: Test Category | D1: Test Sub-category | E1: Feature / Module | F1: Test Description | G1: Platform / Type | H1: Preconditions | I1: Test Steps | J1: Expected Result | K1: Actual Result | L1: Status | M1: Priority | N1: Severity | O1: Tester | P1: Test Date | Q1: Comments
A2: EPIC-00 | B2: TC-CEPA-001-001 | C2: Functional | D2: Inicio de sesión | E2: Servicio de autenticación JWT | F2: Verificar que un usuario activo con credenciales válidas obtiene un token JWT firmado sobre SSL/TLS y es redirigido al panel de su rol | G2: Web/API | H2: Usuario activo existente (ej. perfil Administrativo) con credenciales conocidas; sistema desplegado con certificado TLS válido | I2: 1. Navegar a la pantalla de inicio de sesión por HTTPS. 2. Ingresar usuario 'admin.cepa' y contraseña válida 'Cepa2026!'. 3. Hacer clic en 'Ingresar'. 4. Inspeccionar la respuesta del endpoint /api/v1/auth/login (token emitido y firma). | J2: El sistema emite un token JWT firmado, lo entrega sobre conexión SSL/TLS y redirige al panel correspondiente al rol del usuario | M2: P0 | N2: Critical | Q2: S1
A3: EPIC-00 | B3: TC-CEPA-001-002 | C3: Functional | D3: Renovación de sesión | E3: Servicio de refresh de tokens | F3: Verificar que la sesión se renueva de forma transparente con el refresh token vigente cuando el token de acceso expira | G3: Web/API | H3: Sesión activa con access token expirado (expiración corta) y refresh token vigente | I3: 1. Iniciar sesión y esperar (o forzar) la expiración del access token. 2. Ejecutar una acción que requiere token (ej. GET /api/v1/usuarios/me). 3. Observar el flujo de renovación contra /api/v1/auth/refresh. | J3: El sistema renueva el JWT usando el refresh token sin solicitar credenciales nuevamente y la acción del usuario se completa de forma transparente | M3: P0 | N3: Critical | Q3: S1
A4: EPIC-00 | B4: TC-CEPA-001-003 | C4: Security | D4: Bloqueo por intentos fallidos | E4: Control de intentos de autenticación | F4: Verificar que la cuenta se bloquea temporalmente al alcanzar N intentos fallidos y el evento queda en el log de auditoría | G4: Web/API | H4: Usuario activo con N-1 intentos fallidos previos consecutivos; parámetro N configurado (ej. N=5) | I4: 1. En la pantalla de login, ingresar usuario 'admin.cepa' con contraseña errónea 'ClaveMala1'. 2. Confirmar el intento fallido N. 3. Intentar iniciar sesión con la contraseña correcta. 4. Consultar el log de auditoría con sesión Coordinación. | J4: La cuenta queda bloqueada temporalmente (rechaza incluso credenciales correctas durante el bloqueo) y el evento de bloqueo queda registrado en el log de auditoría | M4: P0 | N4: Critical | Q4: S3
A5: EPIC-00 | B5: TC-CEPA-001-004 | C5: Security | D5: Rechazo de acceso no autorizado | E5: Middleware de autorización API | F5: Verificar que la API rechaza peticiones sin cifrado o con token inválido/expirado con HTTP 401 sin exponer datos | G5: API | H5: Endpoint protegido disponible (ej. GET /api/v1/pacientes); token JWT expirado y token con firma alterada preparados | I5: 1. Llamar al endpoint protegido sin encabezado Authorization. 2. Llamar al endpoint con token expirado. 3. Llamar al endpoint con token de firma inválida. 4. Intentar conectarse al endpoint por HTTP plano (sin TLS). | J5: En todos los casos el sistema responde con código HTTP de no autorizado (401) o rechaza la conexión no cifrada, sin exponer datos sensibles en el cuerpo de la respuesta | M5: P0 | N5: Critical | Q5: S3
A6: EPIC-00 | B6: TC-CEPA-001-005 | C6: Business Rules | D6: Desbloqueo de cuenta | E6: Control de intentos de autenticación | F6: Verificar que una cuenta bloqueada se desbloquea por transcurso del tiempo configurado o por intervención de Coordinación | G6: Web | H6: Cuenta de usuario bloqueada temporalmente por N intentos fallidos; tiempo de bloqueo configurado (ej. 15 minutos); sesión Coordinación disponible | I6: 1. Con la cuenta bloqueada, esperar a que transcurra el tiempo de bloqueo configurado. 2. Iniciar sesión con credenciales correctas. 3. Bloquear nuevamente la cuenta. 4. Con sesión Coordinación, desbloquear manualmente la cuenta desde gestión de usuarios. 5. Iniciar sesión con credenciales correctas. | J6: En ambos escenarios (por tiempo y por intervención de Coordinación) el usuario recupera el acceso e inicia sesión correctamente tras el desbloqueo | M6: P0 | N6: Major | Q6: BR-3
A7: EPIC-00 | B7: TC-CEPA-001-006 | C7: Security | D7: Contenido del payload JWT | E7: Servicio de autenticación JWT | F7: Verificar que el payload del JWT solo porta identidad de usuario y rol, sin datos sensibles de salud mental | G7: API | H7: Usuario activo con acceso a módulos con datos clínicos; sesión iniciada correctamente | I7: 1. Iniciar sesión con usuario válido y capturar el token JWT emitido. 2. Decodificar el payload del JWT (Base64). 3. Revisar los claims presentes en el payload. | J7: El payload contiene únicamente identidad de usuario y rol (y claims técnicos estándar); no incluye ningún dato clínico ni sensible de salud mental de pacientes | M7: P0 | N7: Critical | Q7: BR-4
A8: EPIC-00 | B8: TC-CEPA-001-007 | C8: Business Rules | D8: Trazabilidad de login | E8: Motor de registro de auditoría | F8: Verificar que todo intento de inicio de sesión (éxito y fallo) genera traza en el log de auditoría | G8: Web | H8: Usuario activo existente; acceso al log de auditoría con sesión Coordinación | I8: 1. Realizar un inicio de sesión exitoso con 'admin.cepa'. 2. Cerrar sesión y realizar un intento fallido con contraseña errónea. 3. Con sesión Coordinación, abrir el log de auditoría y filtrar por el usuario y la fecha actual. | J8: El log muestra una traza por el login exitoso y otra por el intento fallido, cada una con usuario, tipo de evento y fecha/hora | M8: P0 | N8: Major | Q8: BR-5
A9: EPIC-00 | B9: TC-CEPA-001-008 | C9: Security | D9: Mensaje de error genérico | E9: Servicio de autenticación JWT | F9: Verificar que ante una contraseña incorrecta el sistema rechaza el acceso con mensaje genérico sin revelar qué campo falló | G9: Web | H9: Usuario activo existente 'admin.cepa' | I9: 1. Navegar a la pantalla de inicio de sesión. 2. Ingresar usuario 'admin.cepa' y contraseña errónea 'ClaveMala1'. 3. Hacer clic en 'Ingresar'. 4. Leer el mensaje de error mostrado. | J9: El sistema rechaza el acceso mostrando un mensaje genérico (ej. 'Credenciales inválidas') sin revelar si el error fue en el usuario o en la contraseña | M9: P0 | N9: Major | Q9: TC-legacy
A10: EPIC-00 | B10: TC-CEPA-002-001 | C10: Functional | D10: Alta de usuario | E10: Módulo de gestión de usuarios | F10: Verificar que Coordinación crea un usuario asignándole un perfil válido y este queda habilitado y visible en el listado | G10: Web | H10: Sesión iniciada con perfil Coordinación; módulo de gestión de usuarios disponible | I10: 1. Abrir el módulo de gestión de usuarios. 2. Hacer clic en 'Crear usuario'. 3. Ingresar datos válidos: nombre 'María Pérez', RUT 12.345.678-5, correo 'maria.perez@utalca.cl'. 4. Asignar el perfil 'Administrativo'. 5. Hacer clic en 'Guardar'. 6. Buscar al usuario en el listado e iniciar sesión con la nueva cuenta. | J10: El usuario queda creado y habilitado con los permisos del perfil Administrativo y aparece en el listado de usuarios | M10: P0 | N10: Critical | Q10: S1
A11: EPIC-00 | B11: TC-CEPA-002-002 | C11: Business Rules | D11: Catálogo cerrado de perfiles | E11: Módulo de gestión de usuarios | F11: Verificar que el sistema solo ofrece los perfiles Coordinación, Administrativo y Auditor y no existe el perfil Clínico | G11: Web/API | H11: Sesión iniciada con perfil Coordinación en el formulario de alta de usuario | I11: 1. Abrir el formulario de creación de usuario. 2. Desplegar el selector de perfil y revisar las opciones disponibles. 3. Intentar crear un usuario vía API POST /api/v1/usuarios con rol 'Clinico'. | J11: El selector ofrece únicamente Coordinación, Administrativo y Auditor; el perfil 'Clínico' no está disponible y la API rechaza el rol no permitido con error de validación | M11: P0 | N11: Major | Q11: S4
A12: EPIC-00 | B12: TC-CEPA-002-003 | C12: Security | D12: RBAC solo lectura Auditor | E12: Motor de permisos RBAC | F12: Verificar que el perfil Auditor solo puede leer datos clínicos y toda acción de edición está bloqueada | G12: Web/API | H12: Usuario con perfil Auditor autenticado; existe al menos un registro con datos clínicos (ej. ingreso de paciente) | I12: 1. Iniciar sesión como Auditor. 2. Abrir un módulo con datos clínicos (ej. Ingresos). 3. Verificar la disponibilidad de botones de edición/eliminación en la UI. 4. Intentar editar el registro vía API PUT /api/v1/ingresos/{id} con el token del Auditor. | J12: El sistema permite solo lectura: los controles de edición están deshabilitados/ocultos en la UI y la API responde con código de acceso prohibido sin modificar datos | M12: P0 | N12: Critical | Q12: S3
A13: EPIC-00 | B13: TC-CEPA-002-004 | C13: Security | D13: RBAC gestión de usuarios | E13: Motor de permisos RBAC | F13: Verificar que el perfil Administrativo no puede acceder a la gestión de usuarios ni crear/editar usuarios | G13: Web/API | H13: Usuario con perfil Administrativo autenticado | I13: 1. Iniciar sesión como Administrativo. 2. Intentar abrir el módulo de gestión de usuarios desde el menú. 3. Intentar crear un usuario vía API POST /api/v1/usuarios con el token del Administrativo. | J13: El sistema deniega la operación por falta de permisos tanto en la UI (módulo no accesible) como en la API (código de acceso prohibido) | M13: P0 | N13: Critical | Q13: S3
... A403: EPIC-12 | B403: TC-CEPA-122-007 | C403: Security | D403: Scope IMED | E403: Autorización RBAC de la API | F403: Verificar que un token sin scope IMED recibe 403 Forbidden al intentar enviar una receta electrónica a los endpoints IMED. | G403: API | H403: Endpoints IMED desplegados en QA; JWT válido de un cliente sin scope/permiso IMED; payload de receta electrónica válido para el folio 2026-0001. | I403: 1. Enviar POST a /api/v1/imed/recetas con el payload de receta usando el JWT sin scope IMED. 2. Inspeccionar el código HTTP y el cuerpo de la respuesta. 3. Consultar en el CEPA las recetas del folio 2026-0001 y verificar que no se agregó ninguna. | J403: La API responde 403 Forbidden con JSON de error; ninguna receta queda persistida. | M403: P2 | N403: Major | Q403: TC-legacy

Sheet RTM
A1: US ID | B1: Source | C1: Source ID | D1: Source Description | E1: TC ID | F1: Business Rule(s)
A2: CEPA-001 | B2: AC | C2: CA-1 | D2: Dado usuario activo en login, cuando ingresa credenciales válidas, entonces se emite JWT firmado sobre SSL/TLS y se redirige al panel de su rol | E2: TC-CEPA-001-001 | F2: RN-1, RN-2
A3: CEPA-001 | B3: AC | C3: CA-2 | D3: Dado JWT expirado con refresh vigente, cuando el usuario opera, entonces la sesión se renueva sin pedir credenciales | E3: TC-CEPA-001-002 | F3: RN-1
A4: CEPA-001 | B4: AC | C4: CA-3 | D4: Dado credenciales incorrectas reiteradas, cuando alcanza N intentos fallidos, entonces la cuenta se bloquea temporalmente y se registra en auditoría | E4: TC-CEPA-001-003 | F4: RN-3, RN-5
A5: CEPA-001 | B5: AC | C5: CA-4 | D5: Dado cliente sin cifrado o con token inválido/expirado, cuando envía la petición, entonces se rechaza con HTTP no autorizado sin exponer datos | E5: TC-CEPA-001-004 | F5: RN-2
A6: CEPA-001 | B6: BR | C6: RN-3 | D6: Tras N intentos fallidos la cuenta se bloquea temporalmente; el desbloqueo es por tiempo o por intervención de Coordinación | E6: TC-CEPA-001-005 | F6: RN-3
A7: CEPA-001 | B7: BR | C7: RN-4 | D7: Los datos sensibles de salud mental nunca se incluyen en el payload del JWT; solo identidad de usuario y rol | E7: TC-CEPA-001-006 | F7: RN-4
A8: CEPA-001 | B8: BR | C8: RN-5 | D8: Todo intento de inicio de sesión (éxito, fallo, bloqueo) genera traza en el log de auditoría | E8: TC-CEPA-001-007 | F8: RN-5, RN-3
A9: CEPA-001 | B9: TC | C9: TC-001-03 | D9: Negativo: contraseña incorrecta rechazada con mensaje genérico sin revelar el campo fallido | E9: TC-CEPA-001-008
A10: CEPA-002 | B10: AC | C10: CA-1 | D10: Dado Coordinación en gestión de usuarios, cuando crea un usuario con uno de los 3 perfiles, entonces queda habilitado con esos permisos y visible en el listado | E10: TC-CEPA-002-001 | F10: RN-1, RN-4
A11: CEPA-002 | B11: AC | C11: CA-2 | D11: Dado los 3 perfiles operativos, cuando Coordinación revisa los perfiles disponibles, entonces el sistema no ofrece el perfil Clínico (v4 D1) | E11: TC-CEPA-002-002 | F11: RN-1
A12: CEPA-002 | B12: AC | C12: CA-3 | D12: Dado un Auditor con sesión, cuando abre un módulo con datos clínicos, entonces solo lectura y edición bloqueada | E12: TC-CEPA-002-003 | F12: RN-2, RN-3
A13: CEPA-002 | B13: AC | C13: CA-4 | D13: Dado un Administrativo, cuando solicita crear o editar un usuario, entonces el sistema deniega por falta de permisos | E13: TC-CEPA-002-004 | F13: RN-4, RN-5
A14: CEPA-002 | B14: AC | C14: CA-5 | D14: Dado un usuario que deja el CEPA, cuando Coordinación lo desactiva, entonces pierde el acceso de inmediato y el cambio queda en auditoría | E14: TC-CEPA-002-005 | F14: RN-4, RN-7
A15: CEPA-002 | B15: BR | C15: RN-2 | D15: Permisos diferenciados por módulo: edición (CRUD) vs. solo lectura según la función del usuario | E15: TC-CEPA-002-006 | F15: RN-2, RN-5
A16: CEPA-002 | B16: BR | C16: RN-3 | D16: El Auditor tiene lectura total y acceso al módulo de Auditoría y reportes de cumplimiento, sin edición de datos clínicos | E16: TC-CEPA-002-007 | F16: RN-3, RN-2
A17: CEPA-002 | B17: BR | C17: RN-6 | D17: La cantidad de usuarios por perfil queda abierta; no hay límite fijo de cupos por perfil | E17: TC-CEPA-002-008 | F17: RN-6
A18: CEPA-002 | B18: BR | C18: RN-7 | D18: Toda alta, baja o cambio de rol de un usuario se registra en el log de auditoría | E18: TC-CEPA-002-009 | F18: RN-7
A19: CEPA-003 | B19: AC | C19: CA-1 | D19: Dado una operación CRUD sobre cualquier registro, cuando se confirma, entonces se registra traza con usuario, operación, registro y fecha/hora | E19: TC-CEPA-003-001 | F19: RN-1, RN-2
A20: CEPA-003 | B20: AC | C20: CA-2 | D20: Dado una traza existente, cuando cualquier usuario intenta modificarla o eliminarla, entonces el sistema lo impide: log inmutable | E20: TC-CEPA-003-002 | F20: RN-3
A21: CEPA-003 | B21: AC | C21: CA-3 | D21: Dado acceso al log, cuando Auditor/Coordinación aplica filtros por usuario, módulo, operación y fechas, entonces se muestran las trazas que cumplen los criterios | E21: TC-CEPA-003-003 | F21: RN-4, RN-5
... A32: CEPA-010 | B32: BR | C32: RN-7 | D32: Campos del formulario §7.1.1: folio, mes y fecha de ingreso, fecha DIEP/DIAT, datos del paciente, tipo de derivación, razón social | E32: TC-CEPA-010-007 | F32: RN-7
A33: CEPA-010 | B33: TC | C33: TC-010-06 | D33: Usuario perfil Auditor intenta abrir/guardar formulario de nuevo ingreso; acceso denegado | E33: TC-CEPA-010-008
A34: CEPA-010 | B34: PLANILLA | C34: Ingresos | D34: Hoja 'Ingresos' del Excel CEPA: 846+ registros, 27 columnas (A1:AA846) | E34: TC-CEPA-010-009 | F34: RN-7
A35: CEPA-010 | B35: PLANILLA | C35: Ingresos | D35: Columnas tipo lista de la hoja 'Ingresos' (SI/NO, estados, tipos de alta) deben ser catálogos cerrados | E35: TC-CEPA-010-010 | F35: RN-6
A36: CEPA-010 | B36: PLANILLA | C36: Ingresos | D36: La planilla histórica contiene celdas vacías y valores 'S/D' en columnas no obligatorias | E36: TC-CEPA-010-011 | F36: RN-2
A37: CEPA-011 | B37: AC | C37: CA-1 | D37: Dado un ingreso nuevo sin folio, cuando guarda, el sistema asigna un folio secuencial automático único | E37: TC-CEPA-011-001 | F37: RN-1
A38: CEPA-011 | B38: AC | C38: CA-2 | D38: Dado un reingreso tras alta, cuando se usa folio manual con el folio anterior, el sistema lo acepta y vincula el reingreso | E38: TC-CEPA-011-002 | F38: RN-2, RN-3
A39: CEPA-011 | B39: AC | C39: CA-3 | D39: Dado un ingreso recibido después de las 15:00 lun-jue, cuando se registra, se permite asignar la fecha del día hábil siguiente | E39: TC-CEPA-011-003 | F39: RN-2
A40: CEPA-011 | B40: AC | C40: CA-4 | D40: Dado un mismo RUT con DIAT 2020 y DIEP 2026, cuando se registra el segundo caso, se diferencia reingreso de nueva denuncia por número de siniestro | E40: TC-CEPA-011-004 | F40: RN-4
A41: CEPA-011 | B41: BR | C41: RN-2 | D41: Opción de folio manual para tres casos v4 D2: reingresos, folios pre-asignados del Excel, e ingresos posteriores a las 15:00 | E41: TC-CEPA-011-005 | F41: RN-2
A42: CEPA-011 | B42: BR | C42: RN-3 | D42: Un folio manual no puede colisionar con un folio ya emitido salvo reingreso explícito del mismo paciente | E42: TC-CEPA-011-006 | F42: RN-1, RN-3
A43: CEPA-011 | B43: BR | C43: RN-5 | D43: El contador secuencial automático debe continuar sin saltos no controlados tras un ingreso manual | E43: TC-CEPA-011-007 | F43: RN-1, RN-5
A44: CEPA-011 | B44: TC | C44: TC-011-06 | D44: Usuario perfil Auditor intenta editar folio manualmente; acceso denegado | E44: TC-CEPA-011-008
A45: CEPA-012 | B45: AC | C45: CA-1 | D45: Dado un RUT, nombre o folio existente, cuando se busca, se muestra el paciente con todas sus dimensiones en una sola pantalla | E45: TC-CEPA-012-001 | F45: RN-1, RN-3
A46: CEPA-012 | B46: AC | C46: CA-2 | D46: Dado el estado completo de un caso, cuando se ejecuta la búsqueda, se presenta el consolidado en menos de 10 segundos (OU3) | E46: TC-CEPA-012-002 | F46: RN-2
A47: CEPA-012 | B47: AC | C47: CA-3 | D47: Dado un término sin coincidencias, cuando se busca, el sistema informa que no hay resultados sin error | E47: TC-CEPA-012-003 | F47: RN-5
A48: CEPA-012 | B48: AC | C48: CA-4 | D48: Dado un nombre parcial con coincidencias múltiples, cuando se busca, se listan los pacientes coincidentes para seleccionar | E48: TC-CEPA-012-004 | F48: RN-1
A49: CEPA-012 | B49: BR | C49: RN-4 | D49: El acceso a la vista 360° respeta RBAC; el perfil Auditor accede en solo lectura | E49: TC-CEPA-012-005 | F49: RN-4
A50: CEPA-013 | B50: AC | C50: CA-1 | D50: Dado un ingreso, cuando se registra primera acogida y estado de consentimiento, el sistema guarda fecha y estado en el caso | E50: TC-CEPA-013-001 | F50: RN-1
...

Sheet Resumen Ejecutivo
A1: Test Cases & RTM — Sistema CEPA — generado 2026-07-02
A3: Total Test Cases | B3: =COUNTA('Test Cases'!B2:B403)
A4: Historias de usuario cubiertas | B4: =SUMPRODUCT((COUNTIF(RTM!A2:A403,RTM!A2:A403)>0)/COUNTIF(RTM!A2:A403,RTM!A2:A403))
A6: Por Categoría
A7: Business Rules | B7: =COUNTIF('Test Cases'!C2:C403,"Business Rules")
A8: Data Integrity | B8: =COUNTIF('Test Cases'!C2:C403,"Data Integrity")
A9: Functional | B9: =COUNTIF('Test Cases'!C2:C403,"Functional")
A10: Integration | B10: =COUNTIF('Test Cases'!C2:C403,"Integration")
A11: Performance | B11: =COUNTIF('Test Cases'!C2:C403,"Performance")
A12: Regression | B12: =COUNTIF('Test Cases'!C2:C403,"Regression")
A13: Security | B13: =COUNTIF('Test Cases'!C2:C403,"Security")
A14: UI/UX | B14: =COUNTIF('Test Cases'!C2:C403,"UI/UX")
A16: Por Prioridad
A17: P0 | B17: =COUNTIF('Test Cases'!M2:M403,"P0")
A18: P1 | B18: =COUNTIF('Test Cases'!M2:M403,"P1")
A19: P2 | B19: =COUNTIF('Test Cases'!M2:M403,"P2")
A21: Por Severidad
A22: Critical | B22: =COUNTIF('Test Cases'!N2:N403,"Critical")
A23: Major | B23: =COUNTIF('Test Cases'!N2:N403,"Major")
A24: Medium | B24: =COUNTIF('Test Cases'!N2:N403,"Medium")
A25: Low | B25: =COUNTIF('Test Cases'!N2:N403,"Low")
A27: Por Épica
A28: EPIC-00 | B28: =COUNTIF('Test Cases'!A2:A403,"EPIC-00")
A29: EPIC-01 | B29: =COUNTIF('Test Cases'!A2:A403,"EPIC-01")
A30: EPIC-02 | B30: =COUNTIF('Test Cases'!A2:A403,"EPIC-02")
A31: EPIC-03 | B31: =COUNTIF('Test Cases'!A2:A403,"EPIC-03")
A32: EPIC-04 | B32: =COUNTIF('Test Cases'!A2:A403,"EPIC-04")
A33: EPIC-05 | B33: =COUNTIF('Test Cases'!A2:A403,"EPIC-05")
A34: EPIC-06 | B34: =COUNTIF('Test Cases'!A2:A403,"EPIC-06")
A35: EPIC-07 | B35: =COUNTIF('Test Cases'!A2:A403,"EPIC-07")
A36: EPIC-08 | B36: =COUNTIF('Test Cases'!A2:A403,"EPIC-08")
A37: EPIC-09 | B37: =COUNTIF('Test Cases'!A2:A403,"EPIC-09")
A38: EPIC-10 | B38: =COUNTIF('Test Cases'!A2:A403,"EPIC-10")
A39: EPIC-11 | B39: =COUNTIF('Test Cases'!A2:A403,"EPIC-11")
A40: EPIC-12 | B40: =COUNTIF('Test Cases'!A2:A403,"EPIC-12")
A42: Ejecución
A43: Pass | B43: =COUNTIF('Test Cases'!L2:L403,"Pass")
A44: Fail | B44: =COUNTIF('Test Cases'!L2:L403,"Fail")
A45: Blocked | B45: =COUNTIF('Test Cases'!L2:L403,"Blocked")
